Workbook
Name Slicer_Age_Rating: #N/A
Name Slicer_Century: #N/A
Name Slicer_Duration_Level: #N/A
Name Slicer_Realse_Date: #N/A

Sheet movies
A1: Film_ID | B1: movie_Name | C1: Rate | D1: Votes | E1: Realse_Date | F1: Century | G1: Movie_Duration | H1: Movie_Duration(min) | I1: Duration_Level | J1: Age_Rating | P1: 31000000
A2: 1 | B2: The Shawshank Redemption | C2: 9.3 | D2: =P1/10 -> 3100000 | E2: 1994 | F2: 20 | G2: 2h 22m | H2: 142 | I2: Mid | J2: R | P2: 22000000
A3: 2 | B3: The Godfather | C3: 9.2 | D3: =P2/10 -> 2200000 | E3: 1972 | F3: 20 | G3: 2h 55m | H3: 175 | I3: Long | J3: R | P3: 31000000
A4: 3 | B4: The Dark Knight | C4: 9.1 | D4: =P3/10 -> 3100000 | E4: 2008 | F4: 21 | G4: 2h 32m | H4: 152 | I4: Long | J4: PG-13 | P4: 15000000
A5: 4 | B5: The Godfather Part II | C5: 9 | D5: =P4/10 -> 1500000 | E5: 1974 | F5: 20 | G5: 3h 22m | H5: 202 | I5: Long | J5: R | P5: 953000
A6: 5 | B6: 12 Angry Men | C6: 9 | D6: =P5/10 -> 95300 | E6: 1957 | F6: 20 | G6: 1h 36m | H6: 96 | I6: Short | J6: Approved | P6: 21000000
A7: 6 | B7: The Lord of the Rings: The Return of the King | C7: 9 | D7: =P6/10 -> 2100000 | E7: 2003 | F7: 21 | G7: 3h 21m | H7: 201 | I7: Long | J7: PG-13 | P7: 16000000
A8: 7 | B8: Schindler's List | C8: 9 | D8: =P7/10 -> 1600000 | E8: 1993 | F8: 20 | G8: 3h 15m | H8: 195 | I8: Long | J8: R | P8: 21000000
A9: 8 | B9: The Lord of the Rings: The Fellowship of the Ring | C9: 8.9 | D9: =P8/10 -> 2100000 | E9: 2001 | F9: 21 | G9: 2h 58m | H9: 178 | I9: Long | J9: PG-13 | P9: 24000000
A10: 9 | B10: Pulp Fiction | C10: 8.8 | D10: =P9/10 -> 2400000 | E10: 1994 | F10: 20 | G10: 2h 34m | H10: 154 | I10: Long | J10: R | P10: 871000
A11: 10 | B11: The Good, the Bad and the Ugly | C11: 8.8 | D11: =P10/10 -> 87100 | E11: 1966 | F11: 20 | G11: 2h 58m | H11: 178 | I11: Long | J11: R | P11: 19000000
A12: 11 | B12: The Lord of the Rings: The Two Towers | C12: 8.8 | D12: =P11/10 -> 1900000 | E12: 2002 | F12: 21 | G12: 2h 59m | H12: 179 | I12: Long | J12: PG-13 | P12: 24000000
A13: 12 | B13: Forrest Gump | C13: 8.8 | D13: =P12/10 -> 2400000 | E13: 1994 | F13: 20 | G13: 2h 22m | H13: 142 | I13: Mid | J13: PG-13 | P13: 25000000
... A250: 249 | B250: The Help | C250: 8.1 | D250: =P249/10 -> 52100 | E250: 2011 | F250: 21 | G250: 2h 26m | H250: 146 | I250: Mid | J250: PG-13 | P250: 112000
A251: 232 | B251: The Incredibles | C251: 8 | D251: =P250/10 -> 11200 | E251: 2004 | F251: 21 | G251: 1h 55m | H251: 115 | I251: Mid | J251: PG

Sheet pivot
B2: =GETPIVOTDATA("Rate",pivot!$B$3) -> 9.3 | C2: =GETPIVOTDATA("Rate",pivot!$C$3) -> 8 | D2: =INT(GETPIVOTDATA("Movie_Duration(min)",pivot!$D$3)) -> 131 | E2: =GETPIVOTDATA("movie_Name",pivot!$E$3) -> 250 | F2: =GETPIVOTDATA("Realse_Date",pivot!$F$3) -> 2025 | G2: =GETPIVOTDATA("Realse_Date",pivot!$G$3) -> 1921 | H2: =GETPIVOTDATA("Votes",pivot!$H$3) -> 432295.6
A3: cards | B3: Max of Rate | C3: Min of Rate | D3: Average of Movie_Duration(min) | E3: Count of movie_Name | F3: Max of Realse_Date | G3: Min of Realse_Date | H3: Average of Votes
B4: 9.3 | C4: 8 | D4: 131.844 | E4: 250 | F4: 2025 | G4: 1921 | H4: 432295.6
B8: Row Labels | C8: Count of Film_ID | E8: The Shawshank Redemption | F8: 9.3 | H8: Row Labels | I8: Average of Movie_Duration(min) | K8: Row Labels | L8: Average of Rate
B9: 20 | C9: 147 | E9: The Godfather | F9: 9.2 | H9: 8 | I9: 115 | K9: 1921 | L9: 8.2
B10: 21 | C10: 103 | E10: The Dark Knight | F10: 9.1 | H10: 8.1 | I10: 120.58333 | K10: 1924 | L10: 8.1
B11: Grand Total | C11: 250 | E11: The Godfather Part II | F11: 9 | H11: 8.2 | I11: 130.75 | K11: 1925 | L11: 8.1
E12: 12 Angry Men | F12: 9 | H12: 8.3 | I12: 136.18421 | K12: 1926 | L12: 8.1
E13: The Lord of the Rings: The Return of the King | F13: 9 | H13: 8.4 | I13: 143.8 | K13: 1927 | L13: 8.3
E14: Schindler's List | F14: 9 | H14: 8.5 | I14: 124.04167 | K14: 1928 | L14: 8.1
E15: The Lord of the Rings: The Fellowship of the Ring | F15: 8.9 | H15: 8.6 | I15: 140 | K15: 1931 | L15: 8.4
E16: Pulp Fiction | F16: 8.8 | H16: 8.7 | I16: 142.33333 | K16: 1936 | L16: 8.5
E17: The Good, the Bad and the Ugly | F17: 8.8 | H17: 8.8 | I17: 156.66667 | K17: 1939 | L17: 8.1333333
H18: 8.9 | I18: 178 | K18: 1940 | L18: 8.25
H19: 9 | I19: 173.5 | K19: 1941 | L19: 8.2
H20: 9.1 | I20: 152 | K20: 1942 | L20: 8.3
H21: 9.2 | I21: 175 | K21: 1944 | L21: 8.3
H22: 9.3 | I22: 142 | K22: 1946 | L22: 8.35
H23: Grand Total | I23: 131.844 | K23: 1948 | L23: 8.2
K24: 1949 | L24: 8.1
B25: Row Labels | C25: Average of Votes | E25: Row Labels | F25: Count of Film_ID | K25: 1950 | L25: 8.2333333
B26: 8 | C26: 11200 | E26: Approved | F26: 22 | K26: 1952 | L26: 8.3
B27: 8.1 | C27: 88650 | E27: G | F27: 18 | K27: 1953 | L27: 8.1
B28: 8.2 | C28: 294832.14 | E28: NC-17 | F28: 1 | K28: 1954 | L28: 8.35
B29: 8.3 | C29: 245392.11 | E29: Not Rated | F29: 24 | K29: 1957 | L29: 8.35
B30: 8.4 | C30: 506504 | E30: Passed | F30: 5 | K30: 1958 | L30: 8.2
B31: 8.5 | C31: 593741.67 | E31: PG | F31: 37 | K31: 1959 | L31: 8.2
B32: 8.6 | C32: 882114.29 | E32: PG-13 | F32: 35 | K32: 1960 | L32: 8.4
B33: 8.7 | C33: 1466666.7 | E33: R | F33: 103 | K33: 1961 | L33: 8.25
B34: 8.8 | C34: 1997850 | E34: unknown | F34: 5 | K34: 1962 | L34: 8.4
B35: 8.9 | C35: 2100000 | E35: Grand Total | F35: 250 | K35: 1963 | L35: 8.3
B36: 9 | C36: 1323825 | K36: 1964 | L36: 8.3
B37: 9.1 | C37: 3100000 | K37: 1965 | L37: 8.15
B38: 9.2 | C38: 2200000 | K38: 1966 | L38: 8.45
B39: 9.3 | C39: 3100000 | K39: 1968 | L39: 8.4
B40: Grand Total | C40: 432295.6 | K40: 1971 | L40: 8.2
K41: 1972 | L41: 9.2
K42: 1973 | L42: 8.15
B43: Row Labels | K43: 1974 | L43: 8.55
B44: Long | K44: 1975 | L44: 8.34
...

Sheet dashboard
C1: IMDS Dashboard
